в моем проекте ошибка можешь написать Промт для моей llm с которой я работаю чтобы зафорсить проблему -                    ^^^^^^^^^^^^^^^^^^^^^^^^^^^^^^^^^^^^^^^
  File "/home/runner/Tauction/app.py", line 206, in internal_error
    return render_template('errors/500.html'), 500
           ^^^^^^^^^^^^^^^^^^^^^^^^^^^^^^^^^^
  File "/home/runner/Tauction/.pythonlibs/lib/python3.11/site-packages/flask/templating.py", line 150, in render_template
    return _render(app, template, context)
           ^^^^^^^^^^^^^^^^^^^^^^^^^^^^^^^
  File "/home/runner/Tauction/.pythonlibs/lib/python3.11/site-packages/flask/templating.py", line 127, in _render
    app.update_template_context(context)
  File "/home/runner/Tauction/.pythonlibs/lib/python3.11/site-packages/flask/app.py", line 493, in update_template_context
    context.update(self.ensure_sync(func)())
                   ^^^^^^^^^^^^^^^^^^^^^^^^
  File "/home/runner/Tauction/.pythonlibs/lib/python3.11/site-packages/flask_login/utils.py", line 405, in _user_context_processor
    return dict(current_user=_get_user())
                             ^^^^^^^^^^^
  File "/home/runner/Tauction/.pythonlibs/lib/python3.11/site-packages/flask_login/utils.py", line 370, in _get_user
    current_app.login_manager._load_user()
  File "/home/runner/Tauction/.pythonlibs/lib/python3.11/site-packages/flask_login/login_manager.py", line 364, in _load_user
    user = self._user_callback(user_id)
           ^^^^^^^^^^^^^^^^^^^^^^^^^^^^
  File "/home/runner/Tauction/app.py", line 32, in load_user
    return db_session.get(User, int(user_id))
           ^^^^^^^^^^^^^^^^^^^^^^^^^^^^^^^^^^
  File "/home/runner/Tauction/.pythonlibs/lib/python3.11/site-packages/sqlalchemy/orm/scoping.py", line 1060, in get
    return self._proxied.get(
           ^^^^^^^^^^^^^^^^^^
  File "/home/runner/Tauction/.pythonlibs/lib/python3.11/site-packages/sqlalchemy/orm/session.py", line 3693, in get
    return self._get_impl(
           ^^^^^^^^^^^^^^^
  File "/home/runner/Tauction/.pythonlibs/lib/python3.11/site-packages/sqlalchemy/orm/session.py", line 3873, in _get_impl
    return db_load_fn(
           ^^^^^^^^^^^
  File "/home/runner/Tauction/.pythonlibs/lib/python3.11/site-packages/sqlalchemy/orm/loading.py", line 694, in load_on_pk_identity
    session.execute(
  File "/home/runner/Tauction/.pythonlibs/lib/python3.11/site-packages/sqlalchemy/orm/session.py", line 2362, in execute
    return self._execute_internal(
           ^^^^^^^^^^^^^^^^^^^^^^^
  File "/home/runner/Tauction/.pythonlibs/lib/python3.11/site-packages/sqlalchemy/orm/session.py", line 2247, in _execute_internal
    result: Result[Any] = compile_state_cls.orm_execute_statement(
                          ^^^^^^^^^^^^^^^^^^^^^^^^^^^^^^^^^^^^^^^^
  File "/home/runner/Tauction/.pythonlibs/lib/python3.11/site-packages/sqlalchemy/orm/context.py", line 305, in orm_execute_statement
    result = conn.execute(
             ^^^^^^^^^^^^^
  File "/home/runner/Tauction/.pythonlibs/lib/python3.11/site-packages/sqlalchemy/engine/base.py", line 1418, in execute
    return meth(
           ^^^^^
  File "/home/runner/Tauction/.pythonlibs/lib/python3.11/site-packages/sqlalchemy/sql/elements.py", line 515, in _execute_on_connection
    return connection._execute_clauseelement(
           ^^^^^^^^^^^^^^^^^^^^^^^^^^^^^^^^^^
  File "/home/runner/Tauction/.pythonlibs/lib/python3.11/site-packages/sqlalchemy/engine/base.py", line 1640, in _execute_clauseelement
    ret = self._execute_context(
          ^^^^^^^^^^^^^^^^^^^^^^
  File "/home/runner/Tauction/.pythonlibs/lib/python3.11/site-packages/sqlalchemy/engine/base.py", line 1846, in _execute_context
    return self._exec_single_context(
           ^^^^^^^^^^^^^^^^^^^^^^^^^^
  File "/home/runner/Tauction/.pythonlibs/lib/python3.11/site-packages/sqlalchemy/engine/base.py", line 1986, in _exec_single_context
    self._handle_dbapi_exception(
  File "/home/runner/Tauction/.pythonlibs/lib/python3.11/site-packages/sqlalchemy/engine/base.py", line 2355, in _handle_dbapi_exception
    raise sqlalchemy_exception.with_traceback(exc_info[2]) from e
  File "/home/runner/Tauction/.pythonlibs/lib/python3.11/site-packages/sqlalchemy/engine/base.py", line 1967, in _exec_single_context
    self.dialect.do_execute(
  File "/home/runner/Tauction/.pythonlibs/lib/python3.11/site-packages/sqlalchemy/engine/default.py", line 941, in do_execute
    cursor.execute(statement, parameters)
sqlalchemy.exc.ProgrammingError: (psycopg2.errors.UndefinedColumn) column users.email does not exist
LINE 1: ...id AS users_id, users.username AS users_username, users.emai...
                                                             ^

[SQL: SELECT users.id AS users_id, users.username AS users_username, users.email AS users_email, users.password_hash AS users_password_hash, users.telegram_id AS users_telegram_id, users.xtr_balance AS users_xtr_balance 
FROM users 
WHERE users.id = %(pk_1)s]
[parameters: {'pk_1': 1}]
(Background on this error at: https://sqlalche.me/e/20/f405)
2024-09-30 19:22:34,294 - hypercorn.error - ERROR - Error in ASGI Framework
Traceback (most recent call last):
  File "/home/runner/Tauction/.pythonlibs/lib/python3.11/site-packages/sqlalchemy/engine/base.py", line 1967, in _exec_single_context
    self.dialect.do_execute(
  File "/home/runner/Tauction/.pythonlibs/lib/python3.11/site-packages/sqlalchemy/engine/default.py", line 941, in do_execute
    cursor.execute(statement, parameters)
psycopg2.errors.UndefinedColumn: column users.email does not exist
LINE 1: ...id AS users_id, users.username AS users_username, users.emai...
                                                             ^


The above exception was the direct cause of the following exception:

Traceback (most recent call last):
  File "/home/runner/Tauction/.pythonlibs/lib/python3.11/site-packages/flask/app.py", line 1473, in wsgi_app
    response = self.full_dispatch_request()
               ^^^^^^^^^^^^^^^^^^^^^^^^^^^^
  File "/home/runner/Tauction/.pythonlibs/lib/python3.11/site-packages/flask/app.py", line 882, in full_dispatch_request
    rv = self.handle_user_exception(e)
         ^^^^^^^^^^^^^^^^^^^^^^^^^^^^^
  File "/home/runner/Tauction/.pythonlibs/lib/python3.11/site-packages/flask/app.py", line 880, in full_dispatch_request
    rv = self.dispatch_request()
         ^^^^^^^^^^^^^^^^^^^^^^^
  File "/home/runner/Tauction/.pythonlibs/lib/python3.11/site-packages/flask/app.py", line 865, in dispatch_request
    return self.ensure_sync(self.view_functions[rule.endpoint])(**view_args)  # type: ignore[no-any-return]
           ^^^^^^^^^^^^^^^^^^^^^^^^^^^^^^^^^^^^^^^^^^^^^^^^^^^^^^^^^^^^^^^^^
  File "/home/runner/Tauction/.pythonlibs/lib/python3.11/site-packages/flask_login/utils.py", line 284, in decorated_view
    elif not current_user.is_authenticated:
             ^^^^^^^^^^^^^^^^^^^^^^^^^^^^^
  File "/home/runner/Tauction/.pythonlibs/lib/python3.11/site-packages/werkzeug/local.py", line 318, in __get__
    obj = instance._get_current_object()
          ^^^^^^^^^^^^^^^^^^^^^^^^^^^^^^
  File "/home/runner/Tauction/.pythonlibs/lib/python3.11/site-packages/werkzeug/local.py", line 526, in _get_current_object
    return get_name(local())
                    ^^^^^^^
  File "/home/runner/Tauction/.pythonlibs/lib/python3.11/site-packages/flask_login/utils.py", line 25, in <lambda>
    current_user = LocalProxy(lambda: _get_user())
                                      ^^^^^^^^^^^
  File "/home/runner/Tauction/.pythonlibs/lib/python3.11/site-packages/flask_login/utils.py", line 370, in _get_user
    current_app.login_manager._load_user()
  File "/home/runner/Tauction/.pythonlibs/lib/python3.11/site-packages/flask_login/login_manager.py", line 364, in _load_user
    user = self._user_callback(user_id)
           ^^^^^^^^^^^^^^^^^^^^^^^^^^^^
  File "/home/runner/Tauction/app.py", line 32, in load_user
    return db_session.get(User, int(user_id))
           ^^^^^^^^^^^^^^^^^^^^^^^^^^^^^^^^^^
  File "/home/runner/Tauction/.pythonlibs/lib/python3.11/site-packages/sqlalchemy/orm/scoping.py", line 1060, in get
    return self._proxied.get(
           ^^^^^^^^^^^^^^^^^^
  File "/home/runner/Tauction/.pythonlibs/lib/python3.11/site-packages/sqlalchemy/orm/session.py", line 3693, in get
    return self._get_impl(
           ^^^^^^^^^^^^^^^
  File "/home/runner/Tauction/.pythonlibs/lib/python3.11/site-packages/sqlalchemy/orm/session.py", line 3873, in _get_impl
    return db_load_fn(
           ^^^^^^^^^^^
  File "/home/runner/Tauction/.pythonlibs/lib/python3.11/site-packages/sqlalchemy/orm/loading.py", line 694, in load_on_pk_identity
    session.execute(
  File "/home/runner/Tauction/.pythonlibs/lib/python3.11/site-packages/sqlalchemy/orm/session.py", line 2362, in execute
    return self._execute_internal(
           ^^^^^^^^^^^^^^^^^^^^^^^
  File "/home/runner/Tauction/.pythonlibs/lib/python3.11/site-packages/sqlalchemy/orm/session.py", line 2247, in _execute_internal
    result: Result[Any] = compile_state_cls.orm_execute_statement(
                          ^^^^^^^^^^^^^^^^^^^^^^^^^^^^^^^^^^^^^^^^
  File "/home/runner/Tauction/.pythonlibs/lib/python3.11/site-packages/sqlalchemy/orm/context.py", line 305, in orm_execute_statement
    result = conn.execute(
             ^^^^^^^^^^^^^
  File "/home/runner/Tauction/.pythonlibs/lib/python3.11/site-packages/sqlalchemy/engine/base.py", line 1418, in execute
    return meth(
           ^^^^^
  File "/home/runner/Tauction/.pythonlibs/lib/python3.11/site-packages/sqlalchemy/sql/elements.py", line 515, in _execute_on_connection
    return connection._execute_clauseelement(
           ^^^^^^^^^^^^^^^^^^^^^^^^^^^^^^^^^^
  File "/home/runner/Tauction/.pythonlibs/lib/python3.11/site-packages/sqlalchemy/engine/base.py", line 1640, in _execute_clauseelement
    ret = self._execute_context(
          ^^^^^^^^^^^^^^^^^^^^^^
  File "/home/runner/Tauction/.pythonlibs/lib/python3.11/site-packages/sqlalchemy/engine/base.py", line 1846, in _execute_context
    return self._exec_single_context(
           ^^^^^^^^^^^^^^^^^^^^^^^^^^
  File "/home/runner/Tauction/.pythonlibs/lib/python3.11/site-packages/sqlalchemy/engine/base.py", line 1986, in _exec_single_context
    self._handle_dbapi_exception(
  File "/home/runner/Tauction/.pythonlibs/lib/python3.11/site-packages/sqlalchemy/engine/base.py", line 2355, in _handle_dbapi_exception
    raise sqlalchemy_exception.with_traceback(exc_info[2]) from e
  File "/home/runner/Tauction/.pythonlibs/lib/python3.11/site-packages/sqlalchemy/engine/base.py", line 1967, in _exec_single_context
    self.dialect.do_execute(
  File "/home/runner/Tauction/.pythonlibs/lib/python3.11/site-packages/sqlalchemy/engine/default.py", line 941, in do_execute
    cursor.execute(statement, parameters)
sqlalchemy.exc.ProgrammingError: (psycopg2.errors.UndefinedColumn) column users.email does not exist
LINE 1: ...id AS users_id, users.username AS users_username, users.emai...
                                                             ^

[SQL: SELECT users.id AS users_id, users.username AS users_username, users.email AS users_email, users.password_hash AS users_password_hash, users.telegram_id AS users_telegram_id, users.xtr_balance AS users_xtr_balance 
FROM users 
WHERE users.id = %(pk_1)s]
[parameters: {'pk_1': 1}]
(Background on this error at: https://sqlalche.me/e/20/f405)

During handling of the above exception, another exception occurred:

Traceback (most recent call last):
  File "/home/runner/Tauction/.pythonlibs/lib/python3.11/site-packages/sqlalchemy/engine/base.py", line 1967, in _exec_single_context
    self.dialect.do_execute(
  File "/home/runner/Tauction/.pythonlibs/lib/python3.11/site-packages/sqlalchemy/engine/default.py", line 941, in do_execute
    cursor.execute(statement, parameters)
psycopg2.errors.UndefinedColumn: column users.email does not exist
LINE 1: ...id AS users_id, users.username AS users_username, users.emai...
                                                             ^


The above exception was the direct cause of the following exception:

Traceback (most recent call last):
  File "/home/runner/Tauction/.pythonlibs/lib/python3.11/site-packages/hypercorn/asyncio/task_group.py", line 23, in _handle
    await app(scope, receive, send, sync_spawn, call_soon)
  File "/home/runner/Tauction/.pythonlibs/lib/python3.11/site-packages/hypercorn/app_wrappers.py", line 50, in __call__
    await self.handle_http(scope, receive, send, sync_spawn, call_soon)
  File "/home/runner/Tauction/.pythonlibs/lib/python3.11/site-packages/hypercorn/app_wrappers.py", line 82, in handle_http
    await sync_spawn(self.run_app, environ, partial(call_soon, send))
  File "/nix/store/f98g7xbckgqbkagdvpzc2r6lv3h1p9ki-python3-3.11.9/lib/python3.11/concurrent/futures/thread.py", line 58, in run
    result = self.fn(*self.args, **self.kwargs)
             ^^^^^^^^^^^^^^^^^^^^^^^^^^^^^^^^^^
  File "/home/runner/Tauction/.pythonlibs/lib/python3.11/site-packages/hypercorn/app_wrappers.py", line 104, in run_app
    for output in self.app(environ, start_response):
                  ^^^^^^^^^^^^^^^^^^^^^^^^^^^^^^^^^
  File "/home/runner/Tauction/.pythonlibs/lib/python3.11/site-packages/flask/app.py", line 1498, in __call__
    return self.wsgi_app(environ, start_response)
           ^^^^^^^^^^^^^^^^^^^^^^^^^^^^^^^^^^^^^^
  File "/home/runner/Tauction/.pythonlibs/lib/python3.11/site-packages/flask/app.py", line 1476, in wsgi_app
    response = self.handle_exception(e)
               ^^^^^^^^^^^^^^^^^^^^^^^^
  File "/home/runner/Tauction/.pythonlibs/lib/python3.11/site-packages/flask/app.py", line 823, in handle_exception
    server_error = self.ensure_sync(handler)(server_error)
                   ^^^^^^^^^^^^^^^^^^^^^^^^^^^^^^^^^^^^^^^
  File "/home/runner/Tauction/app.py", line 206, in internal_error
    return render_template('errors/500.html'), 500
           ^^^^^^^^^^^^^^^^^^^^^^^^^^^^^^^^^^
  File "/home/runner/Tauction/.pythonlibs/lib/python3.11/site-packages/flask/templating.py", line 150, in render_template
    return _render(app, template, context)
           ^^^^^^^^^^^^^^^^^^^^^^^^^^^^^^^
  File "/home/runner/Tauction/.pythonlibs/lib/python3.11/site-packages/flask/templating.py", line 127, in _render
    app.update_template_context(context)
  File "/home/runner/Tauction/.pythonlibs/lib/python3.11/site-packages/flask/app.py", line 493, in update_template_context
    context.update(self.ensure_sync(func)())
                   ^^^^^^^^^^^^^^^^^^^^^^^^
  File "/home/runner/Tauction/.pythonlibs/lib/python3.11/site-packages/flask_login/utils.py", line 405, in _user_context_processor
    return dict(current_user=_get_user())
                             ^^^^^^^^^^^
  File "/home/runner/Tauction/.pythonlibs/lib/python3.11/site-packages/flask_login/utils.py", line 370, in _get_user
    current_app.login_manager._load_user()
  File "/home/runner/Tauction/.pythonlibs/lib/python3.11/site-packages/flask_login/login_manager.py", line 364, in _load_user
    user = self._user_callback(user_id)
           ^^^^^^^^^^^^^^^^^^^^^^^^^^^^
  File "/home/runner/Tauction/app.py", line 32, in load_user
    return db_session.get(User, int(user_id))
           ^^^^^^^^^^^^^^^^^^^^^^^^^^^^^^^^^^
  File "/home/runner/Tauction/.pythonlibs/lib/python3.11/site-packages/sqlalchemy/orm/scoping.py", line 1060, in get
    return self._proxied.get(
           ^^^^^^^^^^^^^^^^^^
  File "/home/runner/Tauction/.pythonlibs/lib/python3.11/site-packages/sqlalchemy/orm/session.py", line 3693, in get
    return self._get_impl(
           ^^^^^^^^^^^^^^^
  File "/home/runner/Tauction/.pythonlibs/lib/python3.11/site-packages/sqlalchemy/orm/session.py", line 3873, in _get_impl
    return db_load_fn(
           ^^^^^^^^^^^
  File "/home/runner/Tauction/.pythonlibs/lib/python3.11/site-packages/sqlalchemy/orm/loading.py", line 694, in load_on_pk_identity
    session.execute(
  File "/home/runner/Tauction/.pythonlibs/lib/python3.11/site-packages/sqlalchemy/orm/session.py", line 2362, in execute
    return self._execute_internal(
           ^^^^^^^^^^^^^^^^^^^^^^^
  File "/home/runner/Tauction/.pythonlibs/lib/python3.11/site-packages/sqlalchemy/orm/session.py", line 2247, in _execute_internal
    result: Result[Any] = compile_state_cls.orm_execute_statement(
                          ^^^^^^^^^^^^^^^^^^^^^^^^^^^^^^^^^^^^^^^^
  File "/home/runner/Tauction/.pythonlibs/lib/python3.11/site-packages/sqlalchemy/orm/context.py", line 305, in orm_execute_statement
    result = conn.execute(
             ^^^^^^^^^^^^^
  File "/home/runner/Tauction/.pythonlibs/lib/python3.11/site-packages/sqlalchemy/engine/base.py", line 1418, in execute
    return meth(
           ^^^^^
  File "/home/runner/Tauction/.pythonlibs/lib/python3.11/site-packages/sqlalchemy/sql/elements.py", line 515, in _execute_on_connection
    return connection._execute_clauseelement(
           ^^^^^^^^^^^^^^^^^^^^^^^^^^^^^^^^^^
  File "/home/runner/Tauction/.pythonlibs/lib/python3.11/site-packages/sqlalchemy/engine/base.py", line 1640, in _execute_clauseelement
    ret = self._execute_context(
          ^^^^^^^^^^^^^^^^^^^^^^
  File "/home/runner/Tauction/.pythonlibs/lib/python3.11/site-packages/sqlalchemy/engine/base.py", line 1846, in _execute_context
    return self._exec_single_context(
           ^^^^^^^^^^^^^^^^^^^^^^^^^^
  File "/home/runner/Tauction/.pythonlibs/lib/python3.11/site-packages/sqlalchemy/engine/base.py", line 1986, in _exec_single_context
    self._handle_dbapi_exception(
  File "/home/runner/Tauction/.pythonlibs/lib/python3.11/site-packages/sqlalchemy/engine/base.py", line 2355, in _handle_dbapi_exception
    raise sqlalchemy_exception.with_traceback(exc_info[2]) from e
  File "/home/runner/Tauction/.pythonlibs/lib/python3.11/site-packages/sqlalchemy/engine/base.py", line 1967, in _exec_single_context
    self.dialect.do_execute(
  File "/home/runner/Tauction/.pythonlibs/lib/python3.11/site-packages/sqlalchemy/engine/default.py", line 941, in do_execute
    cursor.execute(statement, parameters)
sqlalchemy.exc.ProgrammingError: (psycopg2.errors.UndefinedColumn) column users.email does not exist
LINE 1: ...id AS users_id, users.username AS users_username, users.emai...
                                                             ^

[SQL: SELECT users.id AS users_id, users.username AS users_username, users.email AS users_email, users.password_hash AS users_password_hash, users.telegram_id AS users_telegram_id, users.xtr_balance AS users_xtr_balance 
FROM users 
WHERE users.id = %(pk_1)s]
[parameters: {'pk_1': 1}]
(Background on this error at: https://sqlalche.me/e/20/f405)
2024-09-30 19:22:40,969 - apscheduler.executors.default - INFO - Running job "update_dutch_auctions (trigger: interval[0:00:10], next run at: 2024-09-30 19:22:50 UTC)" (scheduled at 2024-09-30 19:22:40.961998+00:00)
2024-09-30 19:22:41,139 - apscheduler.executors.default - ERROR - Job "update_dutch_auctions (trigger: interval[0:00:10], next run at: 2024-09-30 19:22:50 UTC)" raised an exception
Traceback (most recent call last):
  File "/home/runner/Tauction/.pythonlibs/lib/python3.11/site-packages/sqlalchemy/engine/base.py", line 1967, in _exec_single_context
    self.dialect.do_execute(
  File "/home/runner/Tauction/.pythonlibs/lib/python3.11/site-packages/sqlalchemy/engine/default.py", line 941, in do_execute
    cursor.execute(statement, parameters)
psycopg2.errors.UndefinedColumn: column auctions.starting_price does not exist
LINE 1: ...le, auctions.description AS auctions_description, auctions.s...
                                                             ^


The above exception was the direct cause of the following exception:

Traceback (most recent call last):
  File "/home/runner/Tauction/.pythonlibs/lib/python3.11/site-packages/apscheduler/executors/base_py3.py", line 30, in run_coroutine_job
    retval = await job.func(*job.args, **job.kwargs)
             ^^^^^^^^^^^^^^^^^^^^^^^^^^^^^^^^^^^^^^^
  File "/home/runner/Tauction/app.py", line 263, in update_dutch_auctions
    ).all()
      ^^^^^
  File "/home/runner/Tauction/.pythonlibs/lib/python3.11/site-packages/sqlalchemy/orm/query.py", line 2673, in all
    return self._iter().all()  # type: ignore
           ^^^^^^^^^^^^
  File "/home/runner/Tauction/.pythonlibs/lib/python3.11/site-packages/sqlalchemy/orm/query.py", line 2827, in _iter
    result: Union[ScalarResult[_T], Result[_T]] = self.session.execute(
                                                  ^^^^^^^^^^^^^^^^^^^^^
  File "/home/runner/Tauction/.pythonlibs/lib/python3.11/site-packages/sqlalchemy/orm/session.py", line 2362, in execute
    return self._execute_internal(
           ^^^^^^^^^^^^^^^^^^^^^^^
  File "/home/runner/Tauction/.pythonlibs/lib/python3.11/site-packages/sqlalchemy/orm/session.py", line 2247, in _execute_internal
    result: Result[Any] = compile_state_cls.orm_execute_statement(
                          ^^^^^^^^^^^^^^^^^^^^^^^^^^^^^^^^^^^^^^^^
  File "/home/runner/Tauction/.pythonlibs/lib/python3.11/site-packages/sqlalchemy/orm/context.py", line 305, in orm_execute_statement
    result = conn.execute(
             ^^^^^^^^^^^^^
  File "/home/runner/Tauction/.pythonlibs/lib/python3.11/site-packages/sqlalchemy/engine/base.py", line 1418, in execute
    return meth(
           ^^^^^
  File "/home/runner/Tauction/.pythonlibs/lib/python3.11/site-packages/sqlalchemy/sql/elements.py", line 515, in _execute_on_connection
    return connection._execute_clauseelement(
           ^^^^^^^^^^^^^^^^^^^^^^^^^^^^^^^^^^
  File "/home/runner/Tauction/.pythonlibs/lib/python3.11/site-packages/sqlalchemy/engine/base.py", line 1640, in _execute_clauseelement
    ret = self._execute_context(
          ^^^^^^^^^^^^^^^^^^^^^^
  File "/home/runner/Tauction/.pythonlibs/lib/python3.11/site-packages/sqlalchemy/engine/base.py", line 1846, in _execute_context
    return self._exec_single_context(
           ^^^^^^^^^^^^^^^^^^^^^^^^^^
  File "/home/runner/Tauction/.pythonlibs/lib/python3.11/site-packages/sqlalchemy/engine/base.py", line 1986, in _exec_single_context
    self._handle_dbapi_exception(
  File "/home/runner/Tauction/.pythonlibs/lib/python3.11/site-packages/sqlalchemy/engine/base.py", line 2355, in _handle_dbapi_exception
    raise sqlalchemy_exception.with_traceback(exc_info[2]) from e
  File "/home/runner/Tauction/.pythonlibs/lib/python3.11/site-packages/sqlalchemy/engine/base.py", line 1967, in _exec_single_context
    self.dialect.do_execute(
  File "/home/runner/Tauction/.pythonlibs/lib/python3.11/site-packages/sqlalchemy/engine/default.py", line 941, in do_execute
    cursor.execute(statement, parameters)
sqlalchemy.exc.ProgrammingError: (psycopg2.errors.UndefinedColumn) column auctions.starting_price does not exist
LINE 1: ...le, auctions.description AS auctions_description, auctions.s...
                                                             ^

[SQL: SELECT auctions.id AS auctions_id, auctions.title AS auctions_title, auctions.description AS auctions_description, auctions.starting_price AS auctions_starting_price, auctions.current_price AS auctions_current_price, auctions.end_time AS auctions_end_time, auctions.is_active AS auctions_is_active, auctions.creator_id AS auctions_creator_id, auctions.auction_type AS auctions_auction_type, auctions.current_dutch_price AS auctions_current_dutch_price, auctions.dutch_price_decrement AS auctions_dutch_price_decrement, auctions.dutch_interval AS auctions_dutch_interval 
FROM auctions 
WHERE auctions.is_active = true AND auctions.auction_type = %(auction_type_1)s]
[parameters: {'auction_type_1': 'DUTCH'}]
(Background on this error at: https://sqlalche.me/e/20/f405)
2024-09-30 19:22:42,214 - httpx - INFO - HTTP Request: POST https://api.telegram.org/bot7942908605:AAHohHYUAUNBklq0CoY2Drhl6x6jROHWxj8/getUpdates "HTTP/1.1 200 OK"
2024-09-30 19:22:50,970 - apscheduler.executors.default - INFO - Running job "update_dutch_auctions (trigger: interval[0:00:10], next run at: 2024-09-30 19:23:00 UTC)" (scheduled at 2024-09-30 19:22:50.961998+00:00)
2024-09-30 19:22:51,028 - apscheduler.executors.default - ERROR - Job "update_dutch_auctions (trigger: interval[0:00:10], next run at: 2024-09-30 19:23:00 UTC)" raised an exception
Traceback (most recent call last):
  File "/home/runner/Tauction/.pythonlibs/lib/python3.11/site-packages/sqlalchemy/engine/base.py", line 1967, in _exec_single_context
    self.dialect.do_execute(
  File "/home/runner/Tauction/.pythonlibs/lib/python3.11/site-packages/sqlalchemy/engine/default.py", line 941, in do_execute
    cursor.execute(statement, parameters)
psycopg2.errors.InFailedSqlTransaction: current transaction is aborted, commands ignored until end of transaction block


The above exception was the direct cause of the following exception:

Traceback (most recent call last):
  File "/home/runner/Tauction/.pythonlibs/lib/python3.11/site-packages/apscheduler/executors/base_py3.py", line 30, in run_coroutine_job
    retval = await job.func(*job.args, **job.kwargs)
             ^^^^^^^^^^^^^^^^^^^^^^^^^^^^^^^^^^^^^^^
  File "/home/runner/Tauction/app.py", line 263, in update_dutch_auctions
    ).all()
      ^^^^^
  File "/home/runner/Tauction/.pythonlibs/lib/python3.11/site-packages/sqlalchemy/orm/query.py", line 2673, in all
    return self._iter().all()  # type: ignore
           ^^^^^^^^^^^^
  File "/home/runner/Tauction/.pythonlibs/lib/python3.11/site-packages/sqlalchemy/orm/query.py", line 2827, in _iter
    result: Union[ScalarResult[_T], Result[_T]] = self.session.execute(
                                                  ^^^^^^^^^^^^^^^^^^^^^
  File "/home/runner/Tauction/.pythonlibs/lib/python3.11/site-packages/sqlalchemy/orm/session.py", line 2362, in execute
    return self._execute_internal(
           ^^^^^^^^^^^^^^^^^^^^^^^
  File "/home/runner/Tauction/.pythonlibs/lib/python3.11/site-packages/sqlalchemy/orm/session.py", line 2247, in _execute_internal
    result: Result[Any] = compile_state_cls.orm_execute_statement(
                          ^^^^^^^^^^^^^^^^^^^^^^^^^^^^^^^^^^^^^^^^
  File "/home/runner/Tauction/.pythonlibs/lib/python3.11/site-packages/sqlalchemy/orm/context.py", line 305, in orm_execute_statement
    result = conn.execute(
             ^^^^^^^^^^^^^
  File "/home/runner/Tauction/.pythonlibs/lib/python3.11/site-packages/sqlalchemy/engine/base.py", line 1418, in execute
    return meth(
           ^^^^^
  File "/home/runner/Tauction/.pythonlibs/lib/python3.11/site-packages/sqlalchemy/sql/elements.py", line 515, in _execute_on_connection
    return connection._execute_clauseelement(
           ^^^^^^^^^^^^^^^^^^^^^^^^^^^^^^^^^^
  File "/home/runner/Tauction/.pythonlibs/lib/python3.11/site-packages/sqlalchemy/engine/base.py", line 1640, in _execute_clauseelement
    ret = self._execute_context(
          ^^^^^^^^^^^^^^^^^^^^^^
  File "/home/runner/Tauction/.pythonlibs/lib/python3.11/site-packages/sqlalchemy/engine/base.py", line 1846, in _execute_context
    return self._exec_single_context(
           ^^^^^^^^^^^^^^^^^^^^^^^^^^
  File "/home/runner/Tauction/.pythonlibs/lib/python3.11/site-packages/sqlalchemy/engine/base.py", line 1986, in _exec_single_context
    self._handle_dbapi_exception(
  File "/home/runner/Tauction/.pythonlibs/lib/python3.11/site-packages/sqlalchemy/engine/base.py", line 2355, in _handle_dbapi_exception
    raise sqlalchemy_exception.with_traceback(exc_info[2]) from e
  File "/home/runner/Tauction/.pythonlibs/lib/python3.11/site-packages/sqlalchemy/engine/base.py", line 1967, in _exec_single_context
    self.dialect.do_execute(
  File "/home/runner/Tauction/.pythonlibs/lib/python3.11/site-packages/sqlalchemy/engine/default.py", line 941, in do_execute
    cursor.execute(statement, parameters)
sqlalchemy.exc.InternalError: (psycopg2.errors.InFailedSqlTransaction) current transaction is aborted, commands ignored until end of transaction block

[SQL: SELECT auctions.id AS auctions_id, auctions.title AS auctions_title, auctions.description AS auctions_description, auctions.starting_price AS auctions_starting_price, auctions.current_price AS auctions_current_price, auctions.end_time AS auctions_end_time, auctions.is_active AS auctions_is_active, auctions.creator_id AS auctions_creator_id, auctions.auction_type AS auctions_auction_type, auctions.current_dutch_price AS auctions_current_dutch_price, auctions.dutch_price_decrement AS auctions_dutch_price_decrement, auctions.dutch_interval AS auctions_dutch_interval 
FROM auctions 
WHERE auctions.is_active = true AND auctions.auction_type = %(auction_type_1)s]
[parameters: {'auction_type_1': 'DUTCH'}]
(Background on this error at: https://sqlalche.me/e/20/2j85)
2024-09-30 19:22:52,388 - httpx - INFO - HTTP Request: POST https://api.telegram.org/bot7942908605:AAHohHYUAUNBklq0CoY2Drhl6x6jROHWxj8/getUpdates "HTTP/1.1 200 OK"
2024-09-30 19:23:00,971 - apscheduler.executors.default - INFO - Running job "update_dutch_auctions (trigger: interval[0:00:10], next run at: 2024-09-30 19:23:10 UTC)" (scheduled at 2024-09-30 19:23:00.961998+00:00)
2024-09-30 19:23:01,029 - apscheduler.executors.default - ERROR - Job "update_dutch_auctions (trigger: interval[0:00:10], next run at: 2024-09-30 19:23:10 UTC)" raised an exception
Traceback (most recent call last):
  File "/home/runner/Tauction/.pythonlibs/lib/python3.11/site-packages/sqlalchemy/engine/base.py", line 1967, in _exec_single_context
    self.dialect.do_execute(
  File "/home/runner/Tauction/.pythonlibs/lib/python3.11/site-packages/sqlalchemy/engine/default.py", line 941, in do_execute
    cursor.execute(statement, parameters)
psycopg2.errors.InFailedSqlTransaction: current transaction is aborted, commands ignored until end of transaction block


The above exception was the direct cause of the following exception:

Traceback (most recent call last):
  File "/home/runner/Tauction/.pythonlibs/lib/python3.11/site-packages/apscheduler/executors/base_py3.py", line 30, in run_coroutine_job
    retval = await job.func(*job.args, **job.kwargs)
             ^^^^^^^^^^^^^^^^^^^^^^^^^^^^^^^^^^^^^^^
  File "/home/runner/Tauction/app.py", line 263, in update_dutch_auctions
    ).all()
      ^^^^^
  File "/home/runner/Tauction/.pythonlibs/lib/python3.11/site-packages/sqlalchemy/orm/query.py", line 2673, in all
    return self._iter().all()  # type: ignore
           ^^^^^^^^^^^^
  File "/home/runner/Tauction/.pythonlibs/lib/python3.11/site-packages/sqlalchemy/orm/query.py", line 2827, in _iter
    result: Union[ScalarResult[_T], Result[_T]] = self.session.execute(
                                                  ^^^^^^^^^^^^^^^^^^^^^
  File "/home/runner/Tauction/.pythonlibs/lib/python3.11/site-packages/sqlalchemy/orm/session.py", line 2362, in execute
    return self._execute_internal(
           ^^^^^^^^^^^^^^^^^^^^^^^
  File "/home/runner/Tauction/.pythonlibs/lib/python3.11/site-packages/sqlalchemy/orm/session.py", line 2247, in _execute_internal
    result: Result[Any] = compile_state_cls.orm_execute_statement(
                          ^^^^^^^^^^^^^^^^^^^^^^^^^^^^^^^^^^^^^^^^
  File "/home/runner/Tauction/.pythonlibs/lib/python3.11/site-packages/sqlalchemy/orm/context.py", line 305, in orm_execute_statement
    result = conn.execute(
             ^^^^^^^^^^^^^
  File "/home/runner/Tauction/.pythonlibs/lib/python3.11/site-packages/sqlalchemy/engine/base.py", line 1418, in execute
    return meth(
           ^^^^^
  File "/home/runner/Tauction/.pythonlibs/lib/python3.11/site-packages/sqlalchemy/sql/elements.py", line 515, in _execute_on_connection
    return connection._execute_clauseelement(
           ^^^^^^^^^^^^^^^^^^^^^^^^^^^^^^^^^^
  File "/home/runner/Tauction/.pythonlibs/lib/python3.11/site-packages/sqlalchemy/engine/base.py", line 1640, in _execute_clauseelement
    ret = self._execute_context(
          ^^^^^^^^^^^^^^^^^^^^^^
  File "/home/runner/Tauction/.pythonlibs/lib/python3.11/site-packages/sqlalchemy/engine/base.py", line 1846, in _execute_context
    return self._exec_single_context(
           ^^^^^^^^^^^^^^^^^^^^^^^^^^
  File "/home/runner/Tauction/.pythonlibs/lib/python3.11/site-packages/sqlalchemy/engine/base.py", line 1986, in _exec_single_context
    self._handle_dbapi_exception(
  File "/home/runner/Tauction/.pythonlibs/lib/python3.11/site-packages/sqlalchemy/engine/base.py", line 2355, in _handle_dbapi_exception
    raise sqlalchemy_exception.with_traceback(exc_info[2]) from e
  File "/home/runner/Tauction/.pythonlibs/lib/python3.11/site-packages/sqlalchemy/engine/base.py", line 1967, in _exec_single_context
    self.dialect.do_execute(
  File "/home/runner/Tauction/.pythonlibs/lib/python3.11/site-packages/sqlalchemy/engine/default.py", line 941, in do_execute
    cursor.execute(statement, parameters)
sqlalchemy.exc.InternalError: (psycopg2.errors.InFailedSqlTransaction) current transaction is aborted, commands ignored until end of transaction block

[SQL: SELECT auctions.id AS auctions_id, auctions.title AS auctions_title, auctions.description AS auctions_description, auctions.starting_price AS auctions_starting_price, auctions.current_price AS auctions_current_price, auctions.end_time AS auctions_end_time, auctions.is_active AS auctions_is_active, auctions.creator_id AS auctions_creator_id, auctions.auction_type AS auctions_auction_type, auctions.current_dutch_price AS auctions_current_dutch_price, auctions.dutch_price_decrement AS auctions_dutch_price_decrement, auctions.dutch_interval AS auctions_dutch_interval 
FROM auctions 
WHERE auctions.is_active = true AND auctions.auction_type = %(auction_type_1)s]
[parameters: {'auction_type_1': 'DUTCH'}]
(Background on this error at: https://sqlalche.me/e/20/2j85)
2024-09-30 19:23:02,566 - httpx - INFO - HTTP Request: POST https://api.telegram.org/bot7942908605:AAHohHYUAUNBklq0CoY2Drhl6x6jROHWxj8/getUpdates "HTTP/1.1 200 OK"
2024-09-30 19:23:05,029 - app - ERROR - Exception on /create_auction [GET]
Traceback (most recent call last):
  File "/home/runner/Tauction/.pythonlibs/lib/python3.11/site-packages/sqlalchemy/engine/base.py", line 1967, in _exec_single_context
    self.dialect.do_execute(
  File "/home/runner/Tauction/.pythonlibs/lib/python3.11/site-packages/sqlalchemy/engine/default.py", line 941, in do_execute
    cursor.execute(statement, parameters)
psycopg2.errors.UndefinedColumn: column users.email does not exist
LINE 1: ...id AS users_id, users.username AS users_username, users.emai...
                                                             ^


The above exception was the direct cause of the following exception:

Traceback (most recent call last):
  File "/home/runner/Tauction/.pythonlibs/lib/python3.11/site-packages/flask/app.py", line 1473, in wsgi_app
    response = self.full_dispatch_request()
               ^^^^^^^^^^^^^^^^^^^^^^^^^^^^
  File "/home/runner/Tauction/.pythonlibs/lib/python3.11/site-packages/flask/app.py", line 882, in full_dispatch_request
    rv = self.handle_user_exception(e)
         ^^^^^^^^^^^^^^^^^^^^^^^^^^^^^
  File "/home/runner/Tauction/.pythonlibs/lib/python3.11/site-packages/flask/app.py", line 880, in full_dispatch_request
    rv = self.dispatch_request()
         ^^^^^^^^^^^^^^^^^^^^^^^
  File "/home/runner/Tauction/.pythonlibs/lib/python3.11/site-packages/flask/app.py", line 865, in dispatch_request
    return self.ensure_sync(self.view_functions[rule.endpoint])(**view_args)  # type: ignore[no-any-return]
           ^^^^^^^^^^^^^^^^^^^^^^^^^^^^^^^^^^^^^^^^^^^^^^^^^^^^^^^^^^^^^^^^^
  File "/home/runner/Tauction/.pythonlibs/lib/python3.11/site-packages/flask_login/utils.py", line 284, in decorated_view
    elif not current_user.is_authenticated:
             ^^^^^^^^^^^^^^^^^^^^^^^^^^^^^
  File "/home/runner/Tauction/.pythonlibs/lib/python3.11/site-packages/werkzeug/local.py", line 318, in __get__
    obj = instance._get_current_object()
          ^^^^^^^^^^^^^^^^^^^^^^^^^^^^^^
  File "/home/runner/Tauction/.pythonlibs/lib/python3.11/site-packages/werkzeug/local.py", line 526, in _get_current_object
    return get_name(local())
                    ^^^^^^^
  File "/home/runner/Tauction/.pythonlibs/lib/python3.11/site-packages/flask_login/utils.py", line 25, in <lambda>
    current_user = LocalProxy(lambda: _get_user())
                                      ^^^^^^^^^^^
  File "/home/runner/Tauction/.pythonlibs/lib/python3.11/site-packages/flask_login/utils.py", line 370, in _get_user
    current_app.login_manager._load_user()
  File "/home/runner/Tauction/.pythonlibs/lib/python3.11/site-packages/flask_login/login_manager.py", line 364, in _load_user
    user = self._user_callback(user_id)
           ^^^^^^^^^^^^^^^^^^^^^^^^^^^^
  File "/home/runner/Tauction/app.py", line 32, in load_user
    return db_session.get(User, int(user_id))
           ^^^^^^^^^^^^^^^^^^^^^^^^^^^^^^^^^^
  File "/home/runner/Tauction/.pythonlibs/lib/python3.11/site-packages/sqlalchemy/orm/scoping.py", line 1060, in get
    return self._proxied.get(
           ^^^^^^^^^^^^^^^^^^
  File "/home/runner/Tauction/.pythonlibs/lib/python3.11/site-packages/sqlalchemy/orm/session.py", line 3693, in get
    return self._get_impl(
           ^^^^^^^^^^^^^^^
  File "/home/runner/Tauction/.pythonlibs/lib/python3.11/site-packages/sqlalchemy/orm/session.py", line 3873, in _get_impl
    return db_load_fn(
           ^^^^^^^^^^^
  File "/home/runner/Tauction/.pythonlibs/lib/python3.11/site-packages/sqlalchemy/orm/loading.py", line 694, in load_on_pk_identity
    session.execute(
  File "/home/runner/Tauction/.pythonlibs/lib/python3.11/site-packages/sqlalchemy/orm/session.py", line 2362, in execute
    return self._execute_internal(
           ^^^^^^^^^^^^^^^^^^^^^^^
  File "/home/runner/Tauction/.pythonlibs/lib/python3.11/site-packages/sqlalchemy/orm/session.py", line 2247, in _execute_internal
    result: Result[Any] = compile_state_cls.orm_execute_statement(
                          ^^^^^^^^^^^^^^^^^^^^^^^^^^^^^^^^^^^^^^^^
  File "/home/runner/Tauction/.pythonlibs/lib/python3.11/site-packages/sqlalchemy/orm/context.py", line 305, in orm_execute_statement
    result = conn.execute(
             ^^^^^^^^^^^^^
  File "/home/runner/Tauction/.pythonlibs/lib/python3.11/site-packages/sqlalchemy/engine/base.py", line 1418, in execute
    return meth(
           ^^^^^
  File "/home/runner/Tauction/.pythonlibs/lib/python3.11/site-packages/sqlalchemy/sql/elements.py", line 515, in _execute_on_connection
    return connection._execute_clauseelement(
           ^^^^^^^^^^^^^^^^^^^^^^^^^^^^^^^^^^
  File "/home/runner/Tauction/.pythonlibs/lib/python3.11/site-packages/sqlalchemy/engine/base.py", line 1640, in _execute_clauseelement
    ret = self._execute_context(
          ^^^^^^^^^^^^^^^^^^^^^^
  File "/home/runner/Tauction/.pythonlibs/lib/python3.11/site-packages/sqlalchemy/engine/base.py", line 1846, in _execute_context
    return self._exec_single_context(
           ^^^^^^^^^^^^^^^^^^^^^^^^^^
  File "/home/runner/Tauction/.pythonlibs/lib/python3.11/site-packages/sqlalchemy/engine/base.py", line 1986, in _exec_single_context
    self._handle_dbapi_exception(
  File "/home/runner/Tauction/.pythonlibs/lib/python3.11/site-packages/sqlalchemy/engine/base.py", line 2355, in _handle_dbapi_exception
    raise sqlalchemy_exception.with_traceback(exc_info[2]) from e
  File "/home/runner/Tauction/.pythonlibs/lib/python3.11/site-packages/sqlalchemy/engine/base.py", line 1967, in _exec_single_context
    self.dialect.do_execute(
  File "/home/runner/Tauction/.pythonlibs/lib/python3.11/site-packages/sqlalchemy/engine/default.py", line 941, in do_execute
    cursor.execute(statement, parameters)
sqlalchemy.exc.ProgrammingError: (psycopg2.errors.UndefinedColumn) column users.email does not exist
LINE 1: ...id AS users_id, users.username AS users_username, users.emai...
                                                             ^

[SQL: SELECT users.id AS users_id, users.username AS users_username, users.email AS users_email, users.password_hash AS users_password_hash, users.telegram_id AS users_telegram_id, users.xtr_balance AS users_xtr_balance 
FROM users 
WHERE users.id = %(pk_1)s]
[parameters: {'pk_1': 1}]
(Background on this error at: https://sqlalche.me/e/20/f405)
[2024-09-30 19:23:05 +0000] [609] [ERROR] Error in ASGI Framework
Traceback (most recent call last):
  File "/home/runner/Tauction/.pythonlibs/lib/python3.11/site-packages/sqlalchemy/engine/base.py", line 1967, in _exec_single_context
    self.dialect.do_execute(
  File "/home/runner/Tauction/.pythonlibs/lib/python3.11/site-packages/sqlalchemy/engine/default.py", line 941, in do_execute
    cursor.execute(statement, parameters)
psycopg2.errors.UndefinedColumn: column users.email does not exist
LINE 1: ...id AS users_id, users.username AS users_username, users.emai...
                                                             ^


The above exception was the direct cause of the following exception:

Traceback (most recent call last):
  File "/home/runner/Tauction/.pythonlibs/lib/python3.11/site-packages/flask/app.py", line 1473, in wsgi_app
    response = self.full_dispatch_request()
               ^^^^^^^^^^^^^^^^^^^^^^^^^^^^
  File "/home/runner/Tauction/.pythonlibs/lib/python3.11/site-packages/flask/app.py", line 882, in full_dispatch_request
    rv = self.handle_user_exception(e)
         ^^^^^^^^^^^^^^^^^^^^^^^^^^^^^
  File "/home/runner/Tauction/.pythonlibs/lib/python3.11/site-packages/flask/app.py", line 880, in full_dispatch_request
    rv = self.dispatch_request()
         ^^^^^^^^^^^^^^^^^^^^^^^
  File "/home/runner/Tauction/.pythonlibs/lib/python3.11/site-packages/flask/app.py", line 865, in dispatch_request
    return self.ensure_sync(self.view_functions[rule.endpoint])(**view_args)  # type: ignore[no-any-return]
           ^^^^^^^^^^^^^^^^^^^^^^^^^^^^^^^^^^^^^^^^^^^^^^^^^^^^^^^^^^^^^^^^^
  File "/home/runner/Tauction/.pythonlibs/lib/python3.11/site-packages/flask_login/utils.py", line 284, in decorated_view
    elif not current_user.is_authenticated:
             ^^^^^^^^^^^^^^^^^^^^^^^^^^^^^
  File "/home/runner/Tauction/.pythonlibs/lib/python3.11/site-packages/werkzeug/local.py", line 318, in __get__
    obj = instance._get_current_object()
          ^^^^^^^^^^^^^^^^^^^^^^^^^^^^^^
  File "/home/runner/Tauction/.pythonlibs/lib/python3.11/site-packages/werkzeug/local.py", line 526, in _get_current_object
    return get_name(local())
                    ^^^^^^^
  File "/home/runner/Tauction/.pythonlibs/lib/python3.11/site-packages/flask_login/utils.py", line 25, in <lambda>
    current_user = LocalProxy(lambda: _get_user())
                                      ^^^^^^^^^^^
  File "/home/runner/Tauction/.pythonlibs/lib/python3.11/site-packages/flask_login/utils.py", line 370, in _get_user
    current_app.login_manager._load_user()
  File "/home/runner/Tauction/.pythonlibs/lib/python3.11/site-packages/flask_login/login_manager.py", line 364, in _load_user
    user = self._user_callback(user_id)
           ^^^^^^^^^^^^^^^^^^^^^^^^^^^^
  File "/home/runner/Tauction/app.py", line 32, in load_user
    return db_session.get(User, int(user_id))
           ^^^^^^^^^^^^^^^^^^^^^^^^^^^^^^^^^^
  File "/home/runner/Tauction/.pythonlibs/lib/python3.11/site-packages/sqlalchemy/orm/scoping.py", line 1060, in get
    return self._proxied.get(
           ^^^^^^^^^^^^^^^^^^
  File "/home/runner/Tauction/.pythonlibs/lib/python3.11/site-packages/sqlalchemy/orm/session.py", line 3693, in get
    return self._get_impl(
           ^^^^^^^^^^^^^^^
  File "/home/runner/Tauction/.pythonlibs/lib/python3.11/site-packages/sqlalchemy/orm/session.py", line 3873, in _get_impl
    return db_load_fn(
           ^^^^^^^^^^^
  File "/home/runner/Tauction/.pythonlibs/lib/python3.11/site-packages/sqlalchemy/orm/loading.py", line 694, in load_on_pk_identity
    session.execute(
  File "/home/runner/Tauction/.pythonlibs/lib/python3.11/site-packages/sqlalchemy/orm/session.py", line 2362, in execute
    return self._execute_internal(
           ^^^^^^^^^^^^^^^^^^^^^^^
  File "/home/runner/Tauction/.pythonlibs/lib/python3.11/site-packages/sqlalchemy/orm/session.py", line 2247, in _execute_internal
    result: Result[Any] = compile_state_cls.orm_execute_statement(
                          ^^^^^^^^^^^^^^^^^^^^^^^^^^^^^^^^^^^^^^^^
  File "/home/runner/Tauction/.pythonlibs/lib/python3.11/site-packages/sqlalchemy/orm/context.py", line 305, in orm_execute_statement
    result = conn.execute(
             ^^^^^^^^^^^^^
  File "/home/runner/Tauction/.pythonlibs/lib/python3.11/site-packages/sqlalchemy/engine/base.py", line 1418, in execute
    return meth(
           ^^^^^
  File "/home/runner/Tauction/.pythonlibs/lib/python3.11/site-packages/sqlalchemy/sql/elements.py", line 515, in _execute_on_connection
    return connection._execute_clauseelement(
           ^^^^^^^^^^^^^^^^^^^^^^^^^^^^^^^^^^
  File "/home/runner/Tauction/.pythonlibs/lib/python3.11/site-packages/sqlalchemy/engine/base.py", line 1640, in _execute_clauseelement
    ret = self._execute_context(
          ^^^^^^^^^^^^^^^^^^^^^^
  File "/home/runner/Tauction/.pythonlibs/lib/python3.11/site-packages/sqlalchemy/engine/base.py", line 1846, in _execute_context
    return self._exec_single_context(
           ^^^^^^^^^^^^^^^^^^^^^^^^^^
  File "/home/runner/Tauction/.pythonlibs/lib/python3.11/site-packages/sqlalchemy/engine/base.py", line 1986, in _exec_single_context
    self._handle_dbapi_exception(
  File "/home/runner/Tauction/.pythonlibs/lib/python3.11/site-packages/sqlalchemy/engine/base.py", line 2355, in _handle_dbapi_exception
    raise sqlalchemy_exception.with_traceback(exc_info[2]) from e
  File "/home/runner/Tauction/.pythonlibs/lib/python3.11/site-packages/sqlalchemy/engine/base.py", line 1967, in _exec_single_context
    self.dialect.do_execute(
  File "/home/runner/Tauction/.pythonlibs/lib/python3.11/site-packages/sqlalchemy/engine/default.py", line 941, in do_execute
    cursor.execute(statement, parameters)
sqlalchemy.exc.ProgrammingError: (psycopg2.errors.UndefinedColumn) column users.email does not exist
LINE 1: ...id AS users_id, users.username AS users_username, users.emai...
                                                             ^

[SQL: SELECT users.id AS users_id, users.username AS users_username, users.email AS users_email, users.password_hash AS users_password_hash, users.telegram_id AS users_telegram_id, users.xtr_balance AS users_xtr_balance 
FROM users 
WHERE users.id = %(pk_1)s]
[parameters: {'pk_1': 1}]
(Background on this error at: https://sqlalche.me/e/20/f405)

During handling of the above exception, another exception occurred:

Traceback (most recent call last):
  File "/home/runner/Tauction/.pythonlibs/lib/python3.11/site-packages/sqlalchemy/engine/base.py", line 1967, in _exec_single_context
    self.dialect.do_execute(
  File "/home/runner/Tauction/.pythonlibs/lib/python3.11/site-packages/sqlalchemy/engine/default.py", line 941, in do_execute
    cursor.execute(statement, parameters)
psycopg2.errors.UndefinedColumn: column users.email does not exist
LINE 1: ...id AS users_id, users.username AS users_username, users.emai...
                                                             ^


The above exception was the direct cause of the following exception:

Traceback (most recent call last):
  File "/home/runner/Tauction/.pythonlibs/lib/python3.11/site-packages/hypercorn/asyncio/task_group.py", line 23, in _handle
    await app(scope, receive, send, sync_spawn, call_soon)
  File "/home/runner/Tauction/.pythonlibs/lib/python3.11/site-packages/hypercorn/app_wrappers.py", line 50, in __call__
    await self.handle_http(scope, receive, send, sync_spawn, call_soon)
  File "/home/runner/Tauction/.pythonlibs/lib/python3.11/site-packages/hypercorn/app_wrappers.py", line 82, in handle_http
    await sync_spawn(self.run_app, environ, partial(call_soon, send))
  File "/nix/store/f98g7xbckgqbkagdvpzc2r6lv3h1p9ki-python3-3.11.9/lib/python3.11/concurrent/futures/thread.py", line 58, in run
    result = self.fn(*self.args, **self.kwargs)
             ^^^^^^^^^^^^^^^^^^^^^^^^^^^^^^^^^^
  File "/home/runner/Tauction/.pythonlibs/lib/python3.11/site-packages/hypercorn/app_wrappers.py", line 104, in run_app
    for output in self.app(environ, start_response):
                  ^^^^^^^^^^^^^^^^^^^^^^^^^^^^^^^^^
  File "/home/runner/Tauction/.pythonlibs/lib/python3.11/site-packages/flask/app.py", line 1498, in __call__
    return self.wsgi_app(environ, start_response)
           ^^^^^^^^^^^^^^^^^^^^^^^^^^^^^^^^^^^^^^
  File "/home/runner/Tauction/.pythonlibs/lib/python3.11/site-packages/flask/app.py", line 1476, in wsgi_app
    response = self.handle_exception(e)
               ^^^^^^^^^^^^^^^^^^^^^^^^
  File "/home/runner/Tauction/.pythonlibs/lib/python3.11/site-packages/flask/app.py", line 823, in handle_exception
    server_error = self.ensure_sync(handler)(server_error)
                   ^^^^^^^^^^^^^^^^^^^^^^^^^^^^^^^^^^^^^^^
  File "/home/runner/Tauction/app.py", line 206, in internal_error
    return render_template('errors/500.html'), 500
           ^^^^^^^^^^^^^^^^^^^^^^^^^^^^^^^^^^
  File "/home/runner/Tauction/.pythonlibs/lib/python3.11/site-packages/flask/templating.py", line 150, in render_template
    return _render(app, template, context)
           ^^^^^^^^^^^^^^^^^^^^^^^^^^^^^^^
  File "/home/runner/Tauction/.pythonlibs/lib/python3.11/site-packages/flask/templating.py", line 127, in _render
    app.update_template_context(context)
  File "/home/runner/Tauction/.pythonlibs/lib/python3.11/site-packages/flask/app.py", line 493, in update_template_context
    context.update(self.ensure_sync(func)())
                   ^^^^^^^^^^^^^^^^^^^^^^^^
  File "/home/runner/Tauction/.pythonlibs/lib/python3.11/site-packages/flask_login/utils.py", line 405, in _user_context_processor
    return dict(current_user=_get_user())
                             ^^^^^^^^^^^
  File "/home/runner/Tauction/.pythonlibs/lib/python3.11/site-packages/flask_login/utils.py", line 370, in _get_user
    current_app.login_manager._load_user()
  File "/home/runner/Tauction/.pythonlibs/lib/python3.11/site-packages/flask_login/login_manager.py", line 364, in _load_user
    user = self._user_callback(user_id)
           ^^^^^^^^^^^^^^^^^^^^^^^^^^^^
  File "/home/runner/Tauction/app.py", line 32, in load_user
    return db_session.get(User, int(user_id))
           ^^^^^^^^^^^^^^^^^^^^^^^^^^^^^^^^^^
  File "/home/runner/Tauction/.pythonlibs/lib/python3.11/site-packages/sqlalchemy/orm/scoping.py", line 1060, in get
    return self._proxied.get(
           ^^^^^^^^^^^^^^^^^^
  File "/home/runner/Tauction/.pythonlibs/lib/python3.11/site-packages/sqlalchemy/orm/session.py", line 3693, in get
    return self._get_impl(
           ^^^^^^^^^^^^^^^
  File "/home/runner/Tauction/.pythonlibs/lib/python3.11/site-packages/sqlalchemy/orm/session.py", line 3873, in _get_impl
    return db_load_fn(
           ^^^^^^^^^^^
  File "/home/runner/Tauction/.pythonlibs/lib/python3.11/site-packages/sqlalchemy/orm/loading.py", line 694, in load_on_pk_identity
    session.execute(
  File "/home/runner/Tauction/.pythonlibs/lib/python3.11/site-packages/sqlalchemy/orm/session.py", line 2362, in execute
    return self._execute_internal(
           ^^^^^^^^^^^^^^^^^^^^^^^
  File "/home/runner/Tauction/.pythonlibs/lib/python3.11/site-packages/sqlalchemy/orm/session.py", line 2247, in _execute_internal
    result: Result[Any] = compile_state_cls.orm_execute_statement(
                          ^^^^^^^^^^^^^^^^^^^^^^^^^^^^^^^^^^^^^^^^
  File "/home/runner/Tauction/.pythonlibs/lib/python3.11/site-packages/sqlalchemy/orm/context.py", line 305, in orm_execute_statement
    result = conn.execute(
             ^^^^^^^^^^^^^
  File "/home/runner/Tauction/.pythonlibs/lib/python3.11/site-packages/sqlalchemy/engine/base.py", line 1418, in execute
    return meth(
           ^^^^^
  File "/home/runner/Tauction/.pythonlibs/lib/python3.11/site-packages/sqlalchemy/sql/elements.py", line 515, in _execute_on_connection
    return connection._execute_clauseelement(
           ^^^^^^^^^^^^^^^^^^^^^^^^^^^^^^^^^^
  File "/home/runner/Tauction/.pythonlibs/lib/python3.11/site-packages/sqlalchemy/engine/base.py", line 1640, in _execute_clauseelement
    ret = self._execute_context(
          ^^^^^^^^^^^^^^^^^^^^^^
  File "/home/runner/Tauction/.pythonlibs/lib/python3.11/site-packages/sqlalchemy/engine/base.py", line 1846, in _execute_context
    return self._exec_single_context(
           ^^^^^^^^^^^^^^^^^^^^^^^^^^
  File "/home/runner/Tauction/.pythonlibs/lib/python3.11/site-packages/sqlalchemy/engine/base.py", line 1986, in _exec_single_context
    self._handle_dbapi_exception(
  File "/home/runner/Tauction/.pythonlibs/lib/python3.11/site-packages/sqlalchemy/engine/base.py", line 2355, in _handle_dbapi_exception
    raise sqlalchemy_exception.with_traceback(exc_info[2]) from e
  File "/home/runner/Tauction/.pythonlibs/lib/python3.11/site-packages/sqlalchemy/engine/base.py", line 1967, in _exec_single_context
    self.dialect.do_execute(
  File "/home/runner/Tauction/.pythonlibs/lib/python3.11/site-packages/sqlalchemy/engine/default.py", line 941, in do_execute
    cursor.execute(statement, parameters)
sqlalchemy.exc.ProgrammingError: (psycopg2.errors.UndefinedColumn) column users.email does not exist
LINE 1: ...id AS users_id, users.username AS users_username, users.emai...
                                                             ^

[SQL: SELECT users.id AS users_id, users.username AS users_username, users.email AS users_email, users.password_hash AS users_password_hash, users.telegram_id AS users_telegram_id, users.xtr_balance AS users_xtr_balance 
FROM users 
WHERE users.id = %(pk_1)s]
[parameters: {'pk_1': 1}]
(Background on this error at: https://sqlalche.me/e/20/f405)
2024-09-30 19:23:05,312 - hypercorn.error - ERROR - Error in ASGI Framework
Traceback (most recent call last):
  File "/home/runner/Tauction/.pythonlibs/lib/python3.11/site-packages/sqlalchemy/engine/base.py", line 1967, in _exec_single_context
    self.dialect.do_execute(
  File "/home/runner/Tauction/.pythonlibs/lib/python3.11/site-packages/sqlalchemy/engine/default.py", line 941, in do_execute
    cursor.execute(statement, parameters)
psycopg2.errors.UndefinedColumn: column users.email does not exist
LINE 1: ...id AS users_id, users.username AS users_username, users.emai...
                                                             ^


The above exception was the direct cause of the following exception:

Traceback (most recent call last):
  File "/home/runner/Tauction/.pythonlibs/lib/python3.11/site-packages/flask/app.py", line 1473, in wsgi_app
    response = self.full_dispatch_request()
               ^^^^^^^^^^^^^^^^^^^^^^^^^^^^
  File "/home/runner/Tauction/.pythonlibs/lib/python3.11/site-packages/flask/app.py", line 882, in full_dispatch_request
    rv = self.handle_user_exception(e)
         ^^^^^^^^^^^^^^^^^^^^^^^^^^^^^
  File "/home/runner/Tauction/.pythonlibs/lib/python3.11/site-packages/flask/app.py", line 880, in full_dispatch_request
    rv = self.dispatch_request()
         ^^^^^^^^^^^^^^^^^^^^^^^
  File "/home/runner/Tauction/.pythonlibs/lib/python3.11/site-packages/flask/app.py", line 865, in dispatch_request
    return self.ensure_sync(self.view_functions[rule.endpoint])(**view_args)  # type: ignore[no-any-return]
           ^^^^^^^^^^^^^^^^^^^^^^^^^^^^^^^^^^^^^^^^^^^^^^^^^^^^^^^^^^^^^^^^^
  File "/home/runner/Tauction/.pythonlibs/lib/python3.11/site-packages/flask_login/utils.py", line 284, in decorated_view
    elif not current_user.is_authenticated:
             ^^^^^^^^^^^^^^^^^^^^^^^^^^^^^
  File "/home/runner/Tauction/.pythonlibs/lib/python3.11/site-packages/werkzeug/local.py", line 318, in __get__
    obj = instance._get_current_object()
          ^^^^^^^^^^^^^^^^^^^^^^^^^^^^^^
  File "/home/runner/Tauction/.pythonlibs/lib/python3.11/site-packages/werkzeug/local.py", line 526, in _get_current_object
    return get_name(local())
                    ^^^^^^^
  File "/home/runner/Tauction/.pythonlibs/lib/python3.11/site-packages/flask_login/utils.py", line 25, in <lambda>
    current_user = LocalProxy(lambda: _get_user())
                                      ^^^^^^^^^^^
  File "/home/runner/Tauction/.pythonlibs/lib/python3.11/site-packages/flask_login/utils.py", line 370, in _get_user
    current_app.login_manager._load_user()
  File "/home/runner/Tauction/.pythonlibs/lib/python3.11/site-packages/flask_login/login_manager.py", line 364, in _load_user
    user = self._user_callback(user_id)
           ^^^^^^^^^^^^^^^^^^^^^^^^^^^^
  File "/home/runner/Tauction/app.py", line 32, in load_user
    return db_session.get(User, int(user_id))
           ^^^^^^^^^^^^^^^^^^^^^^^^^^^^^^^^^^
  File "/home/runner/Tauction/.pythonlibs/lib/python3.11/site-packages/sqlalchemy/orm/scoping.py", line 1060, in get
    return self._proxied.get(
           ^^^^^^^^^^^^^^^^^^
  File "/home/runner/Tauction/.pythonlibs/lib/python3.11/site-packages/sqlalchemy/orm/session.py", line 3693, in get
    return self._get_impl(
           ^^^^^^^^^^^^^^^
  File "/home/runner/Tauction/.pythonlibs/lib/python3.11/site-packages/sqlalchemy/orm/session.py", line 3873, in _get_impl
    return db_load_fn(
           ^^^^^^^^^^^
  File "/home/runner/Tauction/.pythonlibs/lib/python3.11/site-packages/sqlalchemy/orm/loading.py", line 694, in load_on_pk_identity
    session.execute(
  File "/home/runner/Tauction/.pythonlibs/lib/python3.11/site-packages/sqlalchemy/orm/session.py", line 2362, in execute
    return self._execute_internal(
           ^^^^^^^^^^^^^^^^^^^^^^^
  File "/home/runner/Tauction/.pythonlibs/lib/python3.11/site-packages/sqlalchemy/orm/session.py", line 2247, in _execute_internal
    result: Result[Any] = compile_state_cls.orm_execute_statement(
                          ^^^^^^^^^^^^^^^^^^^^^^^^^^^^^^^^^^^^^^^^
  File "/home/runner/Tauction/.pythonlibs/lib/python3.11/site-packages/sqlalchemy/orm/context.py", line 305, in orm_execute_statement
    result = conn.execute(
             ^^^^^^^^^^^^^
  File "/home/runner/Tauction/.pythonlibs/lib/python3.11/site-packages/sqlalchemy/engine/base.py", line 1418, in execute
    return meth(
           ^^^^^
  File "/home/runner/Tauction/.pythonlibs/lib/python3.11/site-packages/sqlalchemy/sql/elements.py", line 515, in _execute_on_connection
    return connection._execute_clauseelement(
           ^^^^^^^^^^^^^^^^^^^^^^^^^^^^^^^^^^
  File "/home/runner/Tauction/.pythonlibs/lib/python3.11/site-packages/sqlalchemy/engine/base.py", line 1640, in _execute_clauseelement
    ret = self._execute_context(
          ^^^^^^^^^^^^^^^^^^^^^^
  File "/home/runner/Tauction/.pythonlibs/lib/python3.11/site-packages/sqlalchemy/engine/base.py", line 1846, in _execute_context
    return self._exec_single_context(
           ^^^^^^^^^^^^^^^^^^^^^^^^^^
  File "/home/runner/Tauction/.pythonlibs/lib/python3.11/site-packages/sqlalchemy/engine/base.py", line 1986, in _exec_single_context
    self._handle_dbapi_exception(
  File "/home/runner/Tauction/.pythonlibs/lib/python3.11/site-packages/sqlalchemy/engine/base.py", line 2355, in _handle_dbapi_exception
    raise sqlalchemy_exception.with_traceback(exc_info[2]) from e
  File "/home/runner/Tauction/.pythonlibs/lib/python3.11/site-packages/sqlalchemy/engine/base.py", line 1967, in _exec_single_context
    self.dialect.do_execute(
  File "/home/runner/Tauction/.pythonlibs/lib/python3.11/site-packages/sqlalchemy/engine/default.py", line 941, in do_execute
    cursor.execute(statement, parameters)
sqlalchemy.exc.ProgrammingError: (psycopg2.errors.UndefinedColumn) column users.email does not exist
LINE 1: ...id AS users_id, users.username AS users_username, users.emai...
                                                             ^

[SQL: SELECT users.id AS users_id, users.username AS users_username, users.email AS users_email, users.password_hash AS users_password_hash, users.telegram_id AS users_telegram_id, users.xtr_balance AS users_xtr_balance 
FROM users 
WHERE users.id = %(pk_1)s]
[parameters: {'pk_1': 1}]
(Background on this error at: https://sqlalche.me/e/20/f405)

During handling of the above exception, another exception occurred:

Traceback (most recent call last):
  File "/home/runner/Tauction/.pythonlibs/lib/python3.11/site-packages/sqlalchemy/engine/base.py", line 1967, in _exec_single_context
    self.dialect.do_execute(
  File "/home/runner/Tauction/.pythonlibs/lib/python3.11/site-packages/sqlalchemy/engine/default.py", line 941, in do_execute
    cursor.execute(statement, parameters)
psycopg2.errors.UndefinedColumn: column users.email does not exist
LINE 1: ...id AS users_id, users.username AS users_username, users.emai...
                                                             ^


The above exception was the direct cause of the following exception:

Traceback (most recent call last):
  File "/home/runner/Tauction/.pythonlibs/lib/python3.11/site-packages/hypercorn/asyncio/task_group.py", line 23, in _handle
    await app(scope, receive, send, sync_spawn, call_soon)
  File "/home/runner/Tauction/.pythonlibs/lib/python3.11/site-packages/hypercorn/app_wrappers.py", line 50, in __call__
    await self.handle_http(scope, receive, send, sync_spawn, call_soon)
  File "/home/runner/Tauction/.pythonlibs/lib/python3.11/site-packages/hypercorn/app_wrappers.py", line 82, in handle_http
    await sync_spawn(self.run_app, environ, partial(call_soon, send))
  File "/nix/store/f98g7xbckgqbkagdvpzc2r6lv3h1p9ki-python3-3.11.9/lib/python3.11/concurrent/futures/thread.py", line 58, in run
    result = self.fn(*self.args, **self.kwargs)
             ^^^^^^^^^^^^^^^^^^^^^^^^^^^^^^^^^^
  File "/home/runner/Tauction/.pythonlibs/lib/python3.11/site-packages/hypercorn/app_wrappers.py", line 104, in run_app
    for output in self.app(environ, start_response):
                  ^^^^^^^^^^^^^^^^^^^^^^^^^^^^^^^^^
  File "/home/runner/Tauction/.pythonlibs/lib/python3.11/site-packages/flask/app.py", line 1498, in __call__
    return self.wsgi_app(environ, start_response)
           ^^^^^^^^^^^^^^^^^^^^^^^^^^^^^^^^^^^^^^
  File "/home/runner/Tauction/.pythonlibs/lib/python3.11/site-packages/flask/app.py", line 1476, in wsgi_app
    response = self.handle_exception(e)
               ^^^^^^^^^^^^^^^^^^^^^^^^
  File "/home/runner/Tauction/.pythonlibs/lib/python3.11/site-packages/flask/app.py", line 823, in handle_exception
    server_error = self.ensure_sync(handler)(server_error)
                   ^^^^^^^^^^^^^^^^^^^^^^^^^^^^^^^^^^^^^^^
  File "/home/runner/Tauction/app.py", line 206, in internal_error
    return render_template('errors/500.html'), 500
           ^^^^^^^^^^^^^^^^^^^^^^^^^^^^^^^^^^
  File "/home/runner/Tauction/.pythonlibs/lib/python3.11/site-packages/flask/templating.py", line 150, in render_template
    return _render(app, template, context)
           ^^^^^^^^^^^^^^^^^^^^^^^^^^^^^^^
  File "/home/runner/Tauction/.pythonlibs/lib/python3.11/site-packages/flask/templating.py", line 127, in _render
    app.update_template_context(context)
  File "/home/runner/Tauction/.pythonlibs/lib/python3.11/site-packages/flask/app.py", line 493, in update_template_context
    context.update(self.ensure_sync(func)())
                   ^^^^^^^^^^^^^^^^^^^^^^^^
  File "/home/runner/Tauction/.pythonlibs/lib/python3.11/site-packages/flask_login/utils.py", line 405, in _user_context_processor
    return dict(current_user=_get_user())
                             ^^^^^^^^^^^
  File "/home/runner/Tauction/.pythonlibs/lib/python3.11/site-packages/flask_login/utils.py", line 370, in _get_user
    current_app.login_manager._load_user()
  File "/home/runner/Tauction/.pythonlibs/lib/python3.11/site-packages/flask_login/login_manager.py", line 364, in _load_user
    user = self._user_callback(user_id)
           ^^^^^^^^^^^^^^^^^^^^^^^^^^^^
  File "/home/runner/Tauction/app.py", line 32, in load_user
    return db_session.get(User, int(user_id))
           ^^^^^^^^^^^^^^^^^^^^^^^^^^^^^^^^^^
  File "/home/runner/Tauction/.pythonlibs/lib/python3.11/site-packages/sqlalchemy/orm/scoping.py", line 1060, in get
    return self._proxied.get(
           ^^^^^^^^^^^^^^^^^^
  File "/home/runner/Tauction/.pythonlibs/lib/python3.11/site-packages/sqlalchemy/orm/session.py", line 3693, in get
    return self._get_impl(
           ^^^^^^^^^^^^^^^
  File "/home/runner/Tauction/.pythonlibs/lib/python3.11/site-packages/sqlalchemy/orm/session.py", line 3873, in _get_impl
    return db_load_fn(
           ^^^^^^^^^^^
  File "/home/runner/Tauction/.pythonlibs/lib/python3.11/site-packages/sqlalchemy/orm/loading.py", line 694, in load_on_pk_identity
    session.execute(
  File "/home/runner/Tauction/.pythonlibs/lib/python3.11/site-packages/sqlalchemy/orm/session.py", line 2362, in execute
    return self._execute_internal(
           ^^^^^^^^^^^^^^^^^^^^^^^
  File "/home/runner/Tauction/.pythonlibs/lib/python3.11/site-packages/sqlalchemy/orm/session.py", line 2247, in _execute_internal
    result: Result[Any] = compile_state_cls.orm_execute_statement(
                          ^^^^^^^^^^^^^^^^^^^^^^^^^^^^^^^^^^^^^^^^
  File "/home/runner/Tauction/.pythonlibs/lib/python3.11/site-packages/sqlalchemy/orm/context.py", line 305, in orm_execute_statement
    result = conn.execute(
             ^^^^^^^^^^^^^
  File "/home/runner/Tauction/.pythonlibs/lib/python3.11/site-packages/sqlalchemy/engine/base.py", line 1418, in execute
    return meth(
           ^^^^^
  File "/home/runner/Tauction/.pythonlibs/lib/python3.11/site-packages/sqlalchemy/sql/elements.py", line 515, in _execute_on_connection
    return connection._execute_clauseelement(
           ^^^^^^^^^^^^^^^^^^^^^^^^^^^^^^^^^^
  File "/home/runner/Tauction/.pythonlibs/lib/python3.11/site-packages/sqlalchemy/engine/base.py", line 1640, in _execute_clauseelement
    ret = self._execute_context(
          ^^^^^^^^^^^^^^^^^^^^^^
  File "/home/runner/Tauction/.pythonlibs/lib/python3.11/site-packages/sqlalchemy/engine/base.py", line 1846, in _execute_context
    return self._exec_single_context(
           ^^^^^^^^^^^^^^^^^^^^^^^^^^
  File "/home/runner/Tauction/.pythonlibs/lib/python3.11/site-packages/sqlalchemy/engine/base.py", line 1986, in _exec_single_context
    self._handle_dbapi_exception(
  File "/home/runner/Tauction/.pythonlibs/lib/python3.11/site-packages/sqlalchemy/engine/base.py", line 2355, in _handle_dbapi_exception
    raise sqlalchemy_exception.with_traceback(exc_info[2]) from e
  File "/home/runner/Tauction/.pythonlibs/lib/python3.11/site-packages/sqlalchemy/engine/base.py", line 1967, in _exec_single_context
    self.dialect.do_execute(
  File "/home/runner/Tauction/.pythonlibs/lib/python3.11/site-packages/sqlalchemy/engine/default.py", line 941, in do_execute
    cursor.execute(statement, parameters)
sqlalchemy.exc.ProgrammingError: (psycopg2.errors.UndefinedColumn) column users.email does not exist
LINE 1: ...id AS users_id, users.username AS users_username, users.emai...
                                                             ^

[SQL: SELECT users.id AS users_id, users.username AS users_username, users.email AS users_email, users.password_hash AS users_password_hash, users.telegram_id AS users_telegram_id, users.xtr_balance AS users_xtr_balance 
FROM users 
WHERE users.id = %(pk_1)s]
[parameters: {'pk_1': 1}]
(Background on this error at: https://sqlalche.me/e/20/f405)