Traceback (most recent call last):
  File "/home/runner/TelegramLoginWidget/.pythonlibs/lib/python3.11/site-packages/telegram/ext/_application.py", line 1079, in __run
    loop.run_until_complete(self.initialize())
  File "/nix/store/f98g7xbckgqbkagdvpzc2r6lv3h1p9ki-python3-3.11.9/lib/python3.11/asyncio/base_events.py", line 630, in run_until_complete
    self._check_running()
  File "/nix/store/f98g7xbckgqbkagdvpzc2r6lv3h1p9ki-python3-3.11.9/lib/python3.11/asyncio/base_events.py", line 589, in _check_running
    raise RuntimeError('This event loop is already running')
RuntimeError: This event loop is already running

During handling of the above exception, another exception occurred:

Traceback (most recent call last):
  File "/home/runner/TelegramLoginWidget/.pythonlibs/lib/python3.11/site-packages/telegram/ext/_application.py", line 1104, in __run
    loop.run_until_complete(self.shutdown())
  File "/nix/store/f98g7xbckgqbkagdvpzc2r6lv3h1p9ki-python3-3.11.9/lib/python3.11/asyncio/base_events.py", line 630, in run_until_complete
    self._check_running()
  File "/nix/store/f98g7xbckgqbkagdvpzc2r6lv3h1p9ki-python3-3.11.9/lib/python3.11/asyncio/base_events.py", line 589, in _check_running
    raise RuntimeError('This event loop is already running')
RuntimeError: This event loop is already running

During handling of the above exception, another exception occurred:

Traceback (most recent call last):
  File "/home/runner/TelegramLoginWidget/app.py", line 348, in <module>
    asyncio.run(main())
  File "/nix/store/f98g7xbckgqbkagdvpzc2r6lv3h1p9ki-python3-3.11.9/lib/python3.11/asyncio/runners.py", line 190, in run
    return runner.run(main)
           ^^^^^^^^^^^^^^^^
  File "/nix/store/f98g7xbckgqbkagdvpzc2r6lv3h1p9ki-python3-3.11.9/lib/python3.11/asyncio/runners.py", line 118, in run
    return self._loop.run_until_complete(task)
           ^^^^^^^^^^^^^^^^^^^^^^^^^^^^^^^^^^^
  File "/nix/store/f98g7xbckgqbkagdvpzc2r6lv3h1p9ki-python3-3.11.9/lib/python3.11/asyncio/base_events.py", line 654, in run_until_complete
    return future.result()
           ^^^^^^^^^^^^^^^
  File "/home/runner/TelegramLoginWidget/app.py", line 324, in main
    bot_task = asyncio.create_task(bot_application.run_polling())
                                   ^^^^^^^^^^^^^^^^^^^^^^^^^^^^^
  File "/home/runner/TelegramLoginWidget/.pythonlibs/lib/python3.11/site-packages/telegram/ext/_application.py", line 881, in run_polling
    return self.__run(
           ^^^^^^^^^^^
  File "/home/runner/TelegramLoginWidget/.pythonlibs/lib/python3.11/site-packages/telegram/ext/_application.py", line 1109, in __run
    loop.close()
  File "/nix/store/f98g7xbckgqbkagdvpzc2r6lv3h1p9ki-python3-3.11.9/lib/python3.11/asyncio/unix_events.py", line 68, in close
    super().close()
  File "/nix/store/f98g7xbckgqbkagdvpzc2r6lv3h1p9ki-python3-3.11.9/lib/python3.11/asyncio/selector_events.py", line 88, in close
    raise RuntimeError("Cannot close a running event loop")
RuntimeError: Cannot close a running event loop
sys:1: RuntimeWarning: coroutine 'Application.shutdown' was never awaited
sys:1: RuntimeWarning: coroutine 'Application.initialize' was never awaited